Workbook
Name ___KK1: #REF!
Name ___LAG1: #REF!
Name ___LAG2: #REF!
Name ___LAG3: #REF!
Name ___REP1: #REF!
Name __KK1: #REF!
Name __KK1: #REF!
Name __KK1: #REF!
Name __LAG1: #REF!
Name __LAG1: #REF!
Name __LAG1: #REF!
Name __LAG2: #REF!
Name __LAG2: #REF!
Name __LAG2: #REF!
Name __LAG3: #REF!
Name __LAG3: #REF!
Name __LAG3: #REF!
Name __REP1: #REF!
Name __REP1: #REF!
Name __REP1: #REF!
Name _KK1: #REF!
Name _KK1: #REF!
Name _KK1: #REF!
Name _LAG1: #REF!
Name _LAG1: #REF!
Name _LAG1: #REF!
Name _LAG2: #REF!
Name _LAG2: #REF!
Name _LAG2: #REF!
Name _LAG3: #REF!
Name _LAG3: #REF!
Name _LAG3: #REF!
Name _REP1: #REF!
Name _REP1: #REF!
Name _REP1: #REF!
Name GENERALES: #REF!
Name GENERALES: #REF!
Name GENERALES: #REF!
Name MENU1: #REF!
Name MENU1: #REF!
Name MENU1: #REF!
Name MENUGRA: #REF!
Name MENUGRA: #REF!
Name MENUGRA: #REF!
Name MENUING: #REF!
Name MENUING: #REF!
Name MENUING: #REF!
Name MENUINGLAG: #REF!
Name MENUINGLAG: #REF!
Name MENUINGLAG: #REF!
Name MENUREP: #REF!
Name MENUREP: #REF!
Name MENUREP: #REF!
Name MENUVER: #REF!
Name MENUVER: #REF!
Name MENUVER: #REF!
Name NOMBRE: #REF!
Name NOMBRE: #REF!
Name NOMBRE: #REF!
Name NOMHEAD: #REF!

Sheet DATOS Y SISTEMA IMPULSIÓN RÍO
A1: 1- DATOS Y SISTEMA IMPULSIÓN RÍO | E1: Observaciones
A2: SISTEMA DE IMPULSIÓN | E2: Números de edificios por manzanas: suma de las cantidades de letras que poseen los primeros apellidos de los integrantes del grupo divido el número de la cantidad de integrantes
A3: Seleccionar un barrio de | B3: 12 | C3: manzanas
A4: Números de lotes/edificios por manzanas | B4: 6 | C4: lotes
A5: Números de pisos tipo | B5: 22 | C5: pisos | E5: Números de pisos por edificios: suma de las cantidades de letras que posee el primer nombre dividido 1,5, más planta baja y 1 subsuelos
A6: Números de departamentos por pisos | B6: 6 | C6: depto
A7: Números de dormitorios por departamentos | B7: 3 | C7: dorm
A8: Números de personas por dormitorios | B8: 2 | C8: pers
A9: Números de personal de servicio por departamento | B9: 1 | C9: pers
A10: Porcentaje de personal de logística por lote | B10: 10 | C10: %
A11: Total de personas de los departamentos | B11: =+B3*B4*(B5*B6*(B7*B8+B9)) -> 66528 | C11: pers
A12: Personales de logística | B12: =(B6*B5)*B10/100*B4*B3 -> 950.4 | C12: funcionarios | E12: Tabla 1
A13: Caudal unitario por persona por departamento | B13: 200 | C13: l/pers/d | D13: Norma 68 | E13: Departamentos
A14: Caudal unitario por trabajadores de logisticas | B14: 50 | C14: l/pers/d | D14: Norma 68 | E14: Oficinas
A15: Caudal medio de bombeo total | B15: =B11*B13+B12*B14 -> 13353120 | C15: l/d
B16: =+B15/1000 -> 13353.12 | C16: m3/d
B17: =+B15/86400 -> 154.55 | C17: l/s
A18: Caudal por lotes/edificios | B18: =+B15/(B3*B4) -> 185460 | C18: l/d/lotes
B19: =+B18/86400 -> 2.1465278 | C19: l/s/lotes
A20: K1 | B20: 1.2 | C20: Consumo Máx. Diario
A21: K2 | B21: 1.5 | C21: Consumo Máx. Horario
A22: K3 | B22: 1.05 | C22: Línea de impulsión
A23: Caudal de bombeo | B23: =B20*B22*B16/86400 -> 0.194733 | C23: m3/s | D23: =+B23*1000 -> 194.733 | E23: l/s
A24: Número de horas de operación de la bomba por día | B24: =(15*2*24)/60 -> 12 | C24: hs | X24: TABLA 3
X25: Diámetro Nominal | Z25: Curva 90 | AI25: Valv. de cierre | AM25: Tee lateral | AN25: Tee 2 salidas | AO25: Valv. de Pie | AQ25: Valv. de retención
A26: Diametro impulsión (fórmula de Bresse) | B26: =1.3*(B23^0.5)*(((B24/24)^(1/4))) -> 0.48239815 | C26: m | X26: DN | Y26: Ref.
A27: Diámetro adop | B27: Alt 1 | C27: Alt 2 | D27: Alt 3 | X27: mm | Y27: (“)
A28: Succión | B28: 550 | C28: 500 | D28: 350 | E28: mm | F28: El de succión debe ser un diámetro superior al de impulsión | X28: 13 | Y28: ½ | Z28: 0.3 | AA28: 0.40 | AB28: 0.5 | AC28: 0.2 | AD28: 0.2 | AE28: 0.3 | AF28: 0.2 | AG28: 0.2 | AH28: 0.4 | AI28: 0.1 | AJ28: 4.9 | AK28: 2.6 | AL28: 0.3 | AM28: 1.0 | AN28: 1.0 | AO28: 3.6 | AP28: 0.4 | AQ28: 1.1 | AR28: 1.6
A29: Impulsión | B29: 500 | C29: 450 | D29: 300 | E29: mm | X29: 19 | Y29: ¾ | Z29: 0.4 | AA29: 0.6 | AB29: 0.7 | AC29: 0.3 | AD29: 0.3 | AE29: 0.4 | AF29: 0.2 | AG29: 0.2 | AH29: 0.5 | AI29: 0.1 | AJ29: 6.7 | AK29: 3.6 | AL29: 0.4 | AM29: 1.4 | AN29: 1.4 | AO29: 5.6 | AP29: 0.5 | AQ29: 1.6 | AR29: 2.4
X30: 25 | Y30: 1 | Z30: 0.5 | AA30: 0.7 | AB30: 0.8 | AC30: 0.4 | AD30: 0.3 | AE30: 0.5 | AF30: 0.2 | AG30: 0.3 | AH30: 0.7 | AI30: 0.2 | AJ30: 8.2 | AK30: 46 | AL30: 0.5 | AM30: 1.7 | AN30: 1.7 | AO30: 7.3 | AP30: 0.7 | AQ30: 2.1 | AR30: 3.2
A31: Verificación de las velocidades: 0,7 < v < 4,0 | X31: 32 | Y31: 1 ¼ | Z31: 0.7 | AA31: 0.9 | AB31: 1.1 | AC31: 0.5 | AD31: 0.4 | AE31: 0.6 | AF31: 0.3 | AG31: 0.4 | AH31: 0.9 | AI31: 0.2 | AJ31: 11.3 | AK31: 5.6 | AL31: 0.7 | AM31: 2.3 | AN31: 2.3 | AO31: 10.0 | AP31: 0.9 | AQ31: 2.7 | AR31: 4.0
A32: Velocidad de Succión: vsucción | B32: =+B23/(PI()*((B28/1000)^2)/4) -> 0.81964217 | C32: =+B23/(PI()*((C28/1000)^2)/4) -> 0.99176703 | D32: =+B23/(PI()*((D28/1000)^2)/4) -> 2.0240143 | E32: m/s | F32: =+IF((B32>=0.7),IF(B32<=4,"Verifica","Aumentar Diametro"),"Disminuir Diametro") -> Verifica | G32: =+IF((C32>=0.7),IF(C32<=4,"Verifica","Aumentar Diametro"),"Disminuir Diametro") -> Verifica | H32: =+IF((D32>=0.7),IF(D32<=4,"Verifica","Aumentar Diametro"),"Disminuir Diametro") -> Verifica | X32: 38 | Y32: 1 ½ | Z32: 0.9 | AA32: 1.1 | AB32: 1.3 | AC32: 0.6 | AD32: 0.5 | AE32: 0.7 | AF32: 0.3 | AG32: 0.5 | AH32: 1.0 | AI32: 0.3 | AJ32: 13.4 | AK32: 6.7 | AL32: 0.9 | AM32: 2.8 | AN32: 2.8 | AO32: 11.6 | AP32: 1.0 | AQ32: 3.2 | AR32: 4.8
A33: Velocidad de impulsión: vimpulsión | B33: =+B23/(PI()*((B29/1000)^2)/4) -> 0.99176703 | C33: =+B23/(PI()*((C29/1000)^2)/4) -> 1.2244037 | D33: =+B23/(PI()*((D29/1000)^2)/4) -> 2.7549084 | E33: m/s | F33: =+IF((B33>=0.7),IF(B33<=4,"Verifica","Aumentar Diametro"),"Disminuir Diametro") -> Verifica | G33: =+IF((C33>=0.7),IF(C33<=4,"Verifica","Aumentar Diametro"),"Disminuir Diametro") -> Verifica | H33: =+IF((D33>=0.7),IF(D33<=4,"Verifica","Aumentar Diametro"),"Disminuir Diametro") -> Verifica | X33: 50 | Y33: 2 | Z33: 1.1 | AA33: 1.4 | AB33: 1.7 | AC33: 0.8 | AD33: 0.6 | AE33: 0.9 | AF33: 0.4 | AG33: 0.7 | AH33: 1.5 | AI33: 0.4 | AJ33: 17.4 | AK33: 8.5 | AL33: 1.1 | AM33: 3.5 | AN33: 3.5 | AO33: 14.0 | AP33: 1.5 | AQ33: 4.2 | AR33: 6.4
X34: 63 | Y34: 2 ½ | Z34: 1.3 | AA34: 1.7 | AB34: 2.0 | AC34: 0.9 | AD34: 0.8 | AE34: 1.0 | AF34: 0.5 | AG34: 0.9 | AH34: 1.9 | AI34: 0.4 | AJ34: 21.0 | AK34: 10.0 | AL34: 1.3 | AM34: 4.3 | AN34: 4.3 | AO34: 17.0 | AP34: 1.9 | AQ34: 5.2 | AR34: 8.1
A35: Pérdida por metro de tuberia | B35: 6.10.2.1 Fórmulas de Fair Whipple – Hsiao para Acero Galvanizado | X35: 75 | Y35: 3 | Z35: 1.6 | AA35: 2.1 | AB35: 2.5 | AC35: 1.2 | AD35: 1.0 | AE35: 1.3 | AF35: 0.6 | AG35: 1.1 | AH35: 2.2 | AI35: 0.5 | AJ35: 26.0 | AK35: 13.0 | AL35: 1.6 | AM35: 5.2 | AN35: 5.2 | AO35: 20.0 | AP35: 2.2 | AQ35: 6.3 | AR35: 9.7
A36: J succion | B36: =+(B23/((27.113*(B28/1000)^2.596)))^(1/0.532) -> 0.0017273059 | C36: =+(B23/((27.113*(C28/1000)^2.596)))^(1/0.532) -> 0.0027501292 | D36: =+(B23/((27.113*(D28/1000)^2.596)))^(1/0.532) -> 0.015675741 | E36: m/m | X36: 100 | Y36: 4 | Z36: 2.1 | AA36: 2.8 | AB36: 3.4 | AC36: 1.5 | AD36: 1.3 | AE36: 1.6 | AF36: 0.7 | AG36: 1.6 | AH36: 3.2 | AI36: 0.7 | AJ36: 34.0 | AK36: 17.0 | AL36: 2.1 | AM36: 6.7 | AN36: 6.7 | AO36: 23.0 | AP36: 3.2 | AQ36: 6.4 | AR36: 12.9
A37: J impulsión | B37: =+(B23/((27.113*(B29/1000)^2.596)))^(1/0.532) -> 0.0027501292 | C37: =+(B23/((27.113*(C29/1000)^2.596)))^(1/0.532) -> 0.0045987086 | D37: =+(B23/((27.113*(D29/1000)^2.596)))^(1/0.532) -> 0.03325893 | E37: m/m | X37: 125 | Y37: 5 | Z37: 2.7 | AA37: 3.7 | AB37: 4.2 | AC37: 1.9 | AD37: 1.6 | AE37: 2.1 | AF37: 0.9 | AG37: 2.0 | AH37: 4.0 | AI37: 0.9 | AJ37: 43.0 | AK37: 21.0 | AL37: 2.7 | AM37: 8.4 | AN37: 8.4 | AO37: 30.0 | AP37: 4.0 | AQ37: 10.4 | AR37: 16.1
X38: 150 | Y38: 6 | Z38: 3.4 | AA38: 4.3 | AB38: 4.9 | AC38: 2.3 | AD38: 1.9 | AE38: 2.5 | AF38: 1.1 | AG38: 2.5 | AH38: 5.0 | AI38: 1.1 | AJ38: 51.0 | AK38: 26.0 | AL38: 3.4 | AM38: 10.0 | AN38: 10.0 | AO38: 39.0 | AP38: 5.0 | AQ38: 12.5 | AR38: 19.3
A39: Pérdidas localizadas | X39: 200 | Y39: 8 | Z39: 4.3 | AA39: 5.5 | AB39: 6.4 | AC39: 3.0 | AD39: 2.4 | AE39: 3.3 | AF39: 1.5 | AG39: 3.5 | AH39: 6.0 | AI39: 1.4 | AJ39: 67.0 | AK39: 34.0 | AL39: 4.3 | AM39: 13.0 | AN39: 13.0 | AO39: 52.0 | AP39: 6.0 | AQ39: 16.0 | AR39: 25.0
A40: Succión | B40: =L50 -> 129.7 | C40: =M50 -> 112.1 | D40: =N50 -> 129 | E40: m.c.a. | F40: Ver ANEXO I al III de la NORMA 68 | X40: 250 | Y40: 10 | Z40: 5.5 | AA40: 6.7 | AB40: 7.9 | AC40: 3.8 | AD40: 3.0 | AE40: 4.1 | AF40: 1.8 | AG40: 4.5 | AH40: 7.5 | AI40: 1.7 | AJ40: 85.0 | AK40: 43.0 | AL40: 5.5 | AM40: 16.0 | AN40: 16.0 | AO40: 65.0 | AP40: 7.5 | AQ40: 20.0 | AR40: 32.0
...

Sheet POTABILIZADORA
A1: 2- POTABILIZADORA
A2: Caudal diario | B2: =+'DATOS Y SISTEMA IMPULSIÓN RÍO'!B16 -> 13353.12 | C2: m3/d | D2: De hoja de datos
A3: Caudal de captación: Qcap
A4: K1 = | B4: =+'DATOS Y SISTEMA IMPULSIÓN RÍO'!B20 -> 1.2
A5: K2 = | B5: =+'DATOS Y SISTEMA IMPULSIÓN RÍO'!B21 -> 1.5
A6: K3 = | B6: =+'DATOS Y SISTEMA IMPULSIÓN RÍO'!B22 -> 1.05
A7: Qcap = | B7: =+B2*B4*B6*1000/86400 -> 194.733 | C7: l/s
D8: Q = v*A
A9: Cámara de aquietamiento | D9: A = Q/v | G9: Parshall | I9: "V"
A10: Velocidad ascencional (4 a 10) = | B10: 8.6 | C10: cm/s
A11: Area de la sección trasversal = | B11: =+(B7/1000)/(B10/100) -> 2.2643372 | C11: m2 | D11: 0.285 | G11: =+G12+D11 -> 0.72334026 | H11: = E | I11: =+H12+D11 -> 2.1498 | J11: = E
A12: Lados del aquietador = | B12: =+B11^0.5 -> 1.5047715 | C12: m | G12: =+B26 -> 0.43834026 | H12: =+H57+H52 -> 1.8648
C13: =D14+D11 -> 3.0026
A14: Tiempo de aquietamiento (30 a 60) = | B14: 31.6 | C14: s | D14: =+B15 -> 2.7176
A15: Profundidad de la cámara de aquietamiento = | B15: =((B7/1000)*(B14))/B11 -> 2.7176 | C15: m
E18: =+F20 -> 1.5047715
F20: =+B12 -> 1.5047715
A24: Canal aforador parshall y su uso como posible mezclador rápido
A25: Ancho de la garganta: W = | B25: 0.305 | C25: m | D25: =B25/2 -> 0.1525 | L25: Garganta: W | N25: Caudal (l/s) | P25: =B7 -> 194.733
A26: Altura del agua a la llegada: H = | B26: =+((B7/1000)/(2.2*B25))^(0.666666666666667) -> 0.43834026 | C26: m | E26: =0.6+0.159 -> 0.759 | L26: Pulg / pies | M26: m | N26: Minima | O26: Maxima | P26: Medio
A27: Altura del escalón del resalto: N = | B27: 0.229 | C27: m | D27: =0.298-0.21 -> 0.088 | L27: 1'' | M27: 0.025
A28: Diferencia entre el piso de llegada y salida: K = | B28: 0.076 | C28: m | L28: 3" | M28: 0.076 | N28: 0.85 | O28: 53.8 | P28: =AVERAGE(N28:O28) -> 27.325
A29: Altura del agua al final de la garganta: h2 = | B29: =0.6*B26 -> 0.26300415 | C29: m | D29: =B26-B30 -> 0.13150208 | E29: =D29+B28 -> 0.20750208 | H29: Parshall | L29: 6" | M29: 0.152 | N29: 1.52 | O29: 110.4 | P29: =AVERAGE(N29:O29) -> 55.96
A30: Altura del agua a la salida: H3 = | B30: =0.7*B26 -> 0.30683818 | C30: m | L30: 9" | M30: 0.229 | N30: 2.55 | O30: 251.9 | P30: =AVERAGE(N30:O30) -> 127.225 | X30: =25.9/100 -> 0.259
A31: Perdida de carga: h1 = | B31: =+B26-B30-B28 -> 0.055502077 | C31: m | L31: 1' | M31: 0.305 | N31: 3.11 | O31: 455.6 | P31: =AVERAGE(N31:O31) -> 229.355
A32: Verificación de velocidad: 2 ≤ | B32: =+B7/1000/(B25*B29) -> 2.4275999 | C32: m/s | D32: =+IF(B32<=2,"No sirve como Mezclador Rápidos","Se pueda usar como Mezclador Rápido") -> Se pueda usar como Mezclador Rápido | H32: =+B25 -> 0.305 | L32: 1 1/2' | M32: 0.457 | N32: 4.25 | O32: 696.2 | P32: =AVERAGE(N32:O32) -> 350.225 | X32: =45.7/100 -> 0.457
A33: A = | B33: 1.372 | C33: m | L33: 2' | M33: 0.61 | N33: 11.89 | O33: 936.7 | P33: =AVERAGE(N33:O33) -> 474.295
A34: 2/3 A = | B34: =2/3*B33 -> 0.91466667 | C34: m | L34: 3' | M34: 0.915 | N34: 17.26 | O34: 1426.3 | P34: =AVERAGE(N34:O34) -> 721.78
L35: 4' | M35: 1.22 | N35: 36.79 | O35: 1921.5 | P35: =AVERAGE(N35:O35) -> 979.145 | X35: =15.2/100 -> 0.152
F36: =+G11 -> 0.72334026 | H36: =+B26 -> 0.43834026 | L36: 5' | M36: 1.525 | N36: 62.8 | O36: 2422 | P36: =AVERAGE(N36:O36) -> 1242.4
A37: Vertedero "V" | D37: En caso de que no verifique Parshall | J37: =+B28 -> 0.076 | L37: 6' | M37: 1.83 | N37: 74.4 | O37: 2929 | P37: =AVERAGE(N37:O37) -> 1501.7
A38: DATOS | H38: =+B27 -> 0.229 | I38: =+B30 -> 0.30683818 | L38: 7' | M38: 2.135 | N38: 115.4 | O38: 3440 | P38: =AVERAGE(N38:O38) -> 1777.7 | X38: =0.178/2 -> 0.089
A39: Q | B39: =B40/1000 -> 0.194733 | C39: m3/s | H39: =+B29 -> 0.26300415 | L39: 8' | M39: 2.44 | N39: 130.7 | O39: 3950 | P39: =AVERAGE(N39:O39) -> 2040.35
A40: Qcap = | B40: =B7 -> 194.733 | C40: l/s | L40: 10' | M40: 3.05 | N40: 200 | O40: 5660 | P40: =AVERAGE(N40:O40) -> 2930
A41: Cd= | B41: 0.6
A42: phi = | B42: 90 | C42: grados
A43: g= | B43: 9.81 | C43: m/s2
A45: CALCULAMOS LA ALTURA MÁXIMA e QUE ES LA ALTURA DE LA LÁMINA DE AGUA EN EL VERTEDERO
A46: Hmax= | B46: =ROUNDUP((B39/((8/15)*B41*((2*9.81)^(1/2))*E46))^(2/5),4) -> 0.3728 | C46: m | D46: tang | E46: =TAN(B42/2) -> 1.6197752
A47: Hadoptado para el triangulo | B47: 0.3
...

Sheet SISTEMA DE IMPULSIÓN AL TANQUE
A1: 3- SISTEMA DE IMPULSIÓN AL TANQUE
A2: Caudal medio | B2: =+POTABILIZADORA!B2 -> 13353.12 | C2: m3/d
A3: Cota de la base de la motobomba | B3: 97 | C3: msnm | D3: Depende del proyecto
A4: Cota de la base de la base del tanque elevado | B4: =+Presiones!I16 -> 97 | C4: msnm
A6: K1 | B6: =+'DATOS Y SISTEMA IMPULSIÓN RÍO'!B20 -> 1.2
A7: Caudal de bombeo | B7: =B6*B2/86400 -> 0.18546 | C7: m3/s | D7: =+B7*1000 -> 185.46 | E7: l/s
A8: Número de horas de operación de la bomba por dia | B8: 12 | C8: hs
A10: Diametro impulsión (fórmula de Bresse) | B10: =1.3*(B7^0.5)*(((B8/24)^(1/4))) -> 0.47077239 | C10: m
A11: Diametro adop | B11: Alt 1 | C11: Alt 2 | D11: Alt 3
A12: Succion | B12: 550 | C12: 500 | D12: 350 | E12: mm
A13: Impulsion | B13: 500 | C13: 450 | D13: 300 | E13: mm
A15: Verificación de las velocidades: 0,6 < v < 3,5
A16: Velocidad de succión: vsucción | B16: =+B7/(PI()*((B12/1000)^2)/4) -> 0.78061159 | C16: =+B7/(PI()*((C12/1000)^2)/4) -> 0.94454002 | D16: =+B7/(PI()*((D12/1000)^2)/4) -> 1.9276327 | E16: m/s | F16: =+IF((B16>=0.7),IF(B16<=4,"Verifica","Aumentar Diametro"),"Disminuir Diametro") -> Verifica | G16: =+IF((C16>=0.7),IF(C16<=4,"Verifica","Aumentar Diametro"),"Disminuir Diametro") -> Verifica | H16: =+IF((D16>=0.7),IF(D16<=4,"Verifica","Aumentar Diametro"),"Disminuir Diametro") -> Verifica
A17: Velocidad de impulsión: vimpulsión | B17: =+B7/(PI()*((B13/1000)^2)/4) -> 0.94454002 | C17: =+B7/(PI()*((C13/1000)^2)/4) -> 1.1660988 | D17: =+B7/(PI()*((D13/1000)^2)/4) -> 2.6237223 | E17: m/s | F17: =+IF((B17>=0.7),IF(B17<=4,"Verifica","Aumentar Diametro"),"Disminuir Diametro") -> Verifica | G17: =+IF((C17>=0.7),IF(C17<=4,"Verifica","Aumentar Diametro"),"Disminuir Diametro") -> Verifica | H17: =+IF((D17>=0.7),IF(D17<=4,"Verifica","Aumentar Diametro"),"Disminuir Diametro") -> Verifica | T17: TABLA 3
T18: Diámetro Nominal | V18: Curva 90 | AE18: Valv. de cierre | AI18: Tee lateral | AJ18: Tee 2 salidas | AK18: Valv. de Pie | AM18: Valv. de retención
A19: Pérdida por metro de tuberia | B19: 6.10.2.1 Fórmulas de Fair Whipple – Hsiao para Acero Galvanizado | T19: DN | U19: Ref.
A20: J succion | B20: =+(B7/((27.113*(B12/1000)^2.596)))^(1/0.532) -> 0.0015759402 | C20: =+(B7/((27.113*(C12/1000)^2.596)))^(1/0.532) -> 0.0025091325 | D20: =+(B7/((27.113*(D12/1000)^2.596)))^(1/0.532) -> 0.014302059 | E20: m/m | T20: mm | U20: (“)
A21: J impulsión | B21: =+(B7/((27.113*(B13/1000)^2.596)))^(1/0.532) -> 0.0025091325 | C21: =+(B7/((27.113*(C13/1000)^2.596)))^(1/0.532) -> 0.0041957189 | D21: =+(B7/((27.113*(D13/1000)^2.596)))^(1/0.532) -> 0.030344415 | E21: m/m | T21: 13 | U21: ½ | V21: 0.3 | W21: 0.40 | X21: 0.5 | Y21: 0.2 | Z21: 0.2 | AA21: 0.3 | AB21: 0.2 | AC21: 0.2 | AD21: 0.4 | AE21: 0.1 | AF21: 4.9 | AG21: 2.6 | AH21: 0.3 | AI21: 1.0 | AJ21: 1.0 | AK21: 3.6 | AL21: 0.4 | AM21: 1.1 | AN21: 1.6
T22: 19 | U22: ¾ | V22: 0.4 | W22: 0.6 | X22: 0.7 | Y22: 0.3 | Z22: 0.3 | AA22: 0.4 | AB22: 0.2 | AC22: 0.2 | AD22: 0.5 | AE22: 0.1 | AF22: 6.7 | AG22: 3.6 | AH22: 0.4 | AI22: 1.4 | AJ22: 1.4 | AK22: 5.6 | AL22: 0.5 | AM22: 1.6 | AN22: 2.4
A23: Pérdidas localizadas | T23: 25 | U23: 1 | V23: 0.5 | W23: 0.7 | X23: 0.8 | Y23: 0.4 | Z23: 0.3 | AA23: 0.5 | AB23: 0.2 | AC23: 0.3 | AD23: 0.7 | AE23: 0.2 | AF23: 8.2 | AG23: 46 | AH23: 0.5 | AI23: 1.7 | AJ23: 1.7 | AK23: 7.3 | AL23: 0.7 | AM23: 2.1 | AN23: 3.2
A24: Succión | B24: =+K31 -> 129.7 | C24: =+L31 -> 112.1 | D24: =+M31 -> 129 | E24: m.c.a. | J24: Pérdidas Localizadas | K24: Anexo, tabla 3 de norma 68 | T24: 32 | U24: 1 ¼ | V24: 0.7 | W24: 0.9 | X24: 1.1 | Y24: 0.5 | Z24: 0.4 | AA24: 0.6 | AB24: 0.3 | AC24: 0.4 | AD24: 0.9 | AE24: 0.2 | AF24: 11.3 | AG24: 5.6 | AH24: 0.7 | AI24: 2.3 | AJ24: 2.3 | AK24: 10.0 | AL24: 0.9 | AM24: 2.7 | AN24: 4.0
A25: Impulsión | B25: =+K37 -> 51.9 | C25: =+L37 -> 43 | D25: =+M37 -> 51.3 | E25: m.c.a. | J25: Succión | K25: =+B12 -> 550 | L25: =+C12 -> 500 | M25: =+D12 -> 350 | T25: 38 | U25: 1 ½ | V25: 0.9 | W25: 1.1 | X25: 1.3 | Y25: 0.6 | Z25: 0.5 | AA25: 0.7 | AB25: 0.3 | AC25: 0.5 | AD25: 1.0 | AE25: 0.3 | AF25: 13.4 | AG25: 6.7 | AH25: 0.9 | AI25: 2.8 | AJ25: 2.8 | AK25: 11.6 | AL25: 1.0 | AM25: 3.2 | AN25: 4.8
J26: Val. De Pie | K26: 90.1 | L26: 78.1 | M26: 90 | N26: Tabla 3, la cuarta desde la derecha | T26: 50 | U26: 2 | V26: 1.1 | W26: 1.4 | X26: 1.7 | Y26: 0.8 | Z26: 0.6 | AA26: 0.9 | AB26: 0.4 | AC26: 0.7 | AD26: 1.5 | AE26: 0.4 | AF26: 17.4 | AG26: 8.5 | AH26: 1.1 | AI26: 3.5 | AJ26: 3.5 | AK26: 14.0 | AL26: 1.5 | AM26: 4.2 | AN26: 6.4
A27: Longitud de tubería | J27: Curva 90 | K27: 7.4 | L27: 6.2 | M27: 7.3 | N27: Tabla 3, la 1ra desde la izquierda | T27: 63 | U27: 2 ½ | V27: 1.3 | W27: 1.7 | X27: 2.0 | Y27: 0.9 | Z27: 0.8 | AA27: 1.0 | AB27: 0.5 | AC27: 0.9 | AD27: 1.9 | AE27: 0.4 | AF27: 21.0 | AG27: 10.0 | AH27: 1.3 | AI27: 4.3 | AJ27: 4.3 | AK27: 17.0 | AL27: 1.9 | AM27: 5.2 | AN27: 8.1
A28: Succión | B28: =+B32+2 -> 7.1 | C28: =+B28 -> 7.1 | D28: =+C28 -> 7.1 | E28: m | J28: Tee 2salida | K28: 22 | L28: 19 | M28: 22 | N28: Tabla 3, 5ta a la derecha | T28: 75 | U28: 3 | V28: 1.6 | W28: 2.1 | X28: 2.5 | Y28: 1.2 | Z28: 1.0 | AA28: 1.3 | AB28: 0.6 | AC28: 1.1 | AD28: 2.2 | AE28: 0.5 | AF28: 26.0 | AG28: 13.0 | AH28: 1.6 | AI28: 5.2 | AJ28: 5.2 | AK28: 20.0 | AL28: 2.2 | AM28: 6.3 | AN28: 9.7
A29: Impulsión | B29: =2035.06+0.3+10.5 -> 2045.86 | C29: =+B29 -> 2045.86 | D29: =+C29 -> 2045.86 | E29: m | J29: Curva 90 | K29: 7.4 | L29: 6.2 | M29: 7.3 | T29: 100 | U29: 4 | V29: 2.1 | W29: 2.8 | X29: 3.4 | Y29: 1.5 | Z29: 1.3 | AA29: 1.6 | AB29: 0.7 | AC29: 1.6 | AD29: 3.2 | AE29: 0.7 | AF29: 34.0 | AG29: 17.0 | AH29: 2.1 | AI29: 6.7 | AJ29: 6.7 | AK29: 23.0 | AL29: 3.2 | AM29: 6.4 | AN29: 12.9
J30: Valv. De Cierre | K30: 2.8 | L30: 2.6 | M30: 2.4 | N30: El dibujo mas grande, globo | T30: 125 | U30: 5 | V30: 2.7 | W30: 3.7 | X30: 4.2 | Y30: 1.9 | Z30: 1.6 | AA30: 2.1 | AB30: 0.9 | AC30: 2.0 | AD30: 4.0 | AE30: 0.9 | AF30: 43.0 | AG30: 21.0 | AH30: 2.7 | AI30: 8.4 | AJ30: 8.4 | AK30: 30.0 | AL30: 4.0 | AM30: 10.4 | AN30: 16.1
A31: Altura topográfica | J31: Total: | K31: =SUM(K26:K30) -> 129.7 | L31: =SUM(L26:L30) -> 112.1 | M31: =SUM(M26:M30) -> 129 | T31: 150 | U31: 6 | V31: 3.4 | W31: 4.3 | X31: 4.9 | Y31: 2.3 | Z31: 1.9 | AA31: 2.5 | AB31: 1.1 | AC31: 2.5 | AD31: 5.0 | AE31: 1.1 | AF31: 51.0 | AG31: 26.0 | AH31: 3.4 | AI31: 10.0 | AJ31: 10.0 | AK31: 39.0 | AL31: 5.0 | AM31: 12.5 | AN31: 19.3
A32: Succión | B32: =1+0.5+POTABILIZADORA!$B$270 -> 5.1 | C32: =+B32 -> 5.1 | D32: =+C32 -> 5.1 | E32: m | J32: Impulsión | K32: =+B13 -> 500 | L32: =+C13 -> 450 | M32: =+D13 -> 300 | T32: 200 | U32: 8 | V32: 4.3 | W32: 5.5 | X32: 6.4 | Y32: 3.0 | Z32: 2.4 | AA32: 3.3 | AB32: 1.5 | AC32: 3.5 | AD32: 6.0 | AE32: 1.4 | AF32: 67.0 | AG32: 34.0 | AH32: 4.3 | AI32: 13.0 | AJ32: 13.0 | AK32: 52.0 | AL32: 6.0 | AM32: 16.0 | AN32: 25.0
A33: Impulsión | B33: 18 | C33: =+B33 -> 18 | D33: =+C33 -> 18 | E33: m | J33: Curva 90 | K33: 6.2 | L33: 5.6 | M33: 6.1 | T33: 250 | U33: 10 | V33: 5.5 | W33: 6.7 | X33: 7.9 | Y33: 3.8 | Z33: 3.0 | AA33: 4.1 | AB33: 1.8 | AC33: 4.5 | AD33: 7.5 | AE33: 1.7 | AF33: 85.0 | AG33: 43.0 | AH33: 5.5 | AI33: 16.0 | AJ33: 16.0 | AK33: 65.0 | AL33: 7.5 | AM33: 20.0 | AN33: 32.0
J34: Valv. De Retenc | K34: 24.1 | L34: 20.1 | M34: 24 | N34: 2do de la derecha | T34: 300 | U34: 11 | V34: 6.1 | W34: 7.9 | X34: 9.5 | Y34: 4.6 | Z34: 3.6 | AA34: 4.8 | AB34: 2.2 | AC34: 5.5 | AD34: 9.0 | AE34: 2.2 | AF34: 102.0 | AG34: 51.0 | AH34: 6.1 | AI34: 19.0 | AJ34: 19.0 | AK34: 78.0 | AL34: 9.0 | AM34: 24.0 | AN34: 38.0
A35: Velocidad en la tubería | J35: Valv. De Cierre | K35: 2.6 | L35: 1.3 | M35: 2.2 | T35: 350 | U35: 12 | V35: 7.3 | W35: 9.5 | X35: 10.5 | Y35: 5.3 | Z35: 4.4 | AA35: 5.4 | AB35: 2.5 | AC35: 6.2 | AD35: 11.0 | AE35: 2.4 | AF35: 120.0 | AG35: 60.0 | AH35: 7.3 | AI35: 22.0 | AJ35: 22.0 | AK35: 90.0 | AL35: 11.0 | AM35: 28.0 | AN35: 45.0
A36: Succión | B36: =+$B$7/(PI()*((B12/1000)^2)/4) -> 0.78061159 | C36: =+$B$7/(PI()*((C12/1000)^2)/4) -> 0.94454002 | D36: =+B7/(PI()*((D12/1000)^2)/4) -> 1.9276327 | E36: m/s | J36: Tee lateral | K36: 19 | L36: 16 | M36: 19 | N36: 6to de la derecha | T36: 400 | U36: 13.5 | V36: 4.4 | W36: 5.6 | X36: 6.5 | Y36: 3.16 | Z36: 2.5 | AA36: 3.4 | AB36: 1.11 | AC36: 3.6 | AD36: 6.1 | AE36: 1.10 | AF36: 67.1 | AG36: 34.1 | AH36: 4.4 | AI36: 13.0 | AJ36: 13.0 | AK36: 52.1 | AL36: 6.1 | AM36: 16.1 | AN36: 25.1
A37: Impulsión | B37: =+$B$7/(PI()*((B13/1000)^2)/4) -> 0.94454002 | C37: =+$B$7/(PI()*((C13/1000)^2)/4) -> 1.1660988 | D37: =+B7/(PI()*((D13/1000)^2)/4) -> 2.6237223 | E37: m/s | J37: Total: | K37: =SUM(K33:K36) -> 51.9 | L37: =SUM(L33:L36) -> 43 | M37: =SUM(M33:M36) -> 51.3 | T37: 450 | U37: 14.8 | V37: 5.6 | W37: 6.8 | X37: 7.10 | Y37: 3.24 | Z37: 3.12 | AA37: 4.15 | AB37: 1.14 | AC37: 4.6 | AD37: 7.6 | AE37: 1.13 | AF37: 85.1 | AG37: 43.1 | AH37: 5.6 | AI37: 16.0 | AJ37: 16.0 | AK37: 65.1 | AL37: 7.6 | AM37: 20.1 | AN37: 32.1
T38: 500 | U38: 16.1 | V38: 6.2 | W38: 7.10 | X38: 9.6 | Y38: 4.7 | Z38: 3.18 | AA38: 4.22 | AB38: 2.8 | AC38: 5.6 | AD38: 9.1 | AE38: 2.6 | AF38: 102.1 | AG38: 51.1 | AH38: 6.2 | AI38: 19.0 | AJ38: 19.0 | AK38: 78.1 | AL38: 9.1 | AM38: 24.1 | AN38: 38.1
A39: Presión de llegada al reservorio | B39: 1 | C39: =+B39 -> 1 | D39: =+C39 -> 1 | E39: m | T39: 550 | U39: 17.4 | V39: 7.4 | W39: 9.6 | X39: 10.6 | Y39: 5.4 | Z39: 4.5 | AA39: 5.5 | AB39: 2.11 | AC39: 6.3 | AD39: 11.1 | AE39: 2.8 | AF39: 120.1 | AG39: 60.1 | AH39: 7.4 | AI39: 22.0 | AJ39: 22.0 | AK39: 90.1 | AL39: 11.1 | AM39: 28.1 | AN39: 45.1
A41: Altura Manométrica o Gradiente Hidraúlico
A42: Succión | B42: =+B32+(B28+B24)*B20+((B36^2)/(2*9.8)) -> 5.3466781 | C42: =+C32+(C28+C24)*C20+((C36^2)/(2*9.8)) -> 5.4446067 | D42: =+D32+(D28+D24)*D20+((D36^2)/(2*9.8)) -> 7.2360902 | E42: m.c.a.
A43: Impulsión | B43: =+B33+(B29+B25)*B21+((B37^2)/(2*9.8)) -> 23.309076 | C43: =+C33+(C29+C25)*C21+((C37^2)/(2*9.8)) -> 26.833646 | D43: =+D33+(D29+D25)*D21+((D37^2)/(2*9.8)) -> 81.988313 | E43: m.c.a.
A44: Total | B44: =+B43+B42+B39 -> 29.655754 | C44: =+C43+C42+C39 -> 33.278253 | D44: =+D43+D42+D39 -> 90.224404 | E44: m.c.a.
...

Sheet Caudales
A2: 4- CAUDALES
A6: 1ra iteración
A7: CIRCUITO | C7: TRAMO | D7: DIAM.(m) | E7: LONG.(m) | F7: CAUDAL (m3/s) | G7: VELOC.(m/s) | H7: J (m/m) | I7: Hi(m) | J7: Hi/Qi | K7: CORRECCIÓN | M7: CAUDAL (m3/s)
A8: PROPIO | B8: COMUN | K8: PROPIA | L8: COMUN
A9: I | C9: ='Datos Inic'!B11 -> AB | D9: ='Datos Inic'!L11 -> 0.2 | E9: ='Datos Inic'!C11 -> 224 | F9: ='Datos Inic'!H11/1000 -> 0.02704625 | G9: =+F9*4/(3.1415*D9^2) -> 0.86093427 | H9: =10.643*140^(-1.85)*D9^(-4.87)*ABS(F9)^1.85*IF(F9<0,-1,1) -> 0.0036316934 | I9: =+H9*E9 -> 0.81349932 | J9: =+I9/F9 -> 30.078082 | K9: =-I13/(J13*1.851) -> -0.01071584 | M9: =+F9+K9+L9 -> 0.01633041
C10: ='Datos Inic'!B12 -> RB | D10: ='Datos Inic'!L12 -> 0.3 | E10: ='Datos Inic'!C12 -> 336 | F10: =-'Datos Inic'!H12/1000 -> -0.077275 | G10: =+F10*4/(3.1415*D10^2) -> -1.0932499 | H10: =10.643*140^(-1.85)*D10^(-4.87)*ABS(F10)^1.85*IF(F10<0,-1,1) -> -0.0035157571 | I10: =+H10*E10 -> -1.1812944 | J10: =+I10/F10 -> 15.286889 | K10: =-I13/(J13*1.851) -> -0.01071584 | M10: =+F10+K10+L10 -> -0.08799084
B11: II | C11: ='Datos Inic'!B13 -> RQ | D11: ='Datos Inic'!L13 -> 0.35 | E11: ='Datos Inic'!C13 -> 224 | F11: ='Datos Inic'!H13/1000 -> 0.1004575 | G11: =+F11*4/(3.1415*D11^2) -> 1.0441652 | H11: =10.643*140^(-1.85)*D11^(-4.87)*ABS(F11)^1.85*IF(F11<0,-1,1) -> 0.002696393 | I11: =+H11*E11 -> 0.60399204 | J11: =+I11/F11 -> 6.0124136 | K11: =-I13/(J13*1.851) -> -0.01071584 | L11: =-K20 -> -0.044018 | M11: =+F11+K11+L11 -> 0.04572366
C12: ='Datos Inic'!B14 -> QA | D12: ='Datos Inic'!L14 -> 0.25 | E12: ='Datos Inic'!C14 -> 336 | F12: ='Datos Inic'!H14/1000 -> 0.05022875 | G12: =+F12*4/(3.1415*D12^2) -> 1.0232819 | H12: =10.643*140^(-1.85)*D12^(-4.87)*ABS(F12)^1.85*IF(F12<0,-1,1) -> 0.0038505365 | I12: =+H12*E12 -> 1.2937802 | J12: =+I12/F12 -> 25.757763 | K12: =-I13/(J13*1.851) -> -0.01071584 | M12: =+F12+K12+L12 -> 0.03951291
H13: SUMA | I13: =+SUM(I9:I12) -> 1.5299772 | J13: =+SUM(J9:J12) -> 77.135148
A15: CIRCUITO | C15: TRAMO | D15: DIAM.(m) | E15: LONG.(m) | F15: CAUDAL (m3/s) | G15: VELOC.(m/s) | H15: J (m/m) | I15: Hi(m) | J15: Hi/Qi | K15: CORRECCIÓN | M15: CAUDAL (m3/s)
A16: PROPIO | B16: COMUN | K16: PROPIA | L16: COMUN
A17: II | C17: ='Datos Inic'!B15 -> HR | D17: ='Datos Inic'!L15 -> 0.25 | E17: ='Datos Inic'!C15 -> 336 | F17: =-'Datos Inic'!H15/1000 -> -0.05022875 | G17: =+F17*4/(3.1415*D17^2) -> -1.0232819 | H17: =10.643*140^(-1.85)*D17^(-4.87)*ABS(F17)^1.85*IF(F17<0,-1,1) -> -0.0038505365 | I17: =+H17*E17 -> -1.2937802 | J17: =+I17/F17 -> 25.757763 | K17: =-I21/(J21*1.851) -> 0.044018 | M17: =+F17+K17+L17 -> -0.0062107499
C18: ='Datos Inic'!B16 -> GH | D18: ='Datos Inic'!L16 -> 0.3 | E18: ='Datos Inic'!C16 -> 224 | F18: =-'Datos Inic'!H16/1000 -> -0.077275 | G18: =+F18*4/(3.1415*D18^2) -> -1.0932499 | H18: =10.643*140^(-1.85)*D18^(-4.87)*ABS(F18)^1.85*IF(F18<0,-1,1) -> -0.0035157571 | I18: =+H18*E18 -> -0.78752959 | J18: =+I18/F18 -> 10.19126 | K18: =-I21/(J21*1.851) -> 0.044018 | M18: =+F18+K18+L18 -> -0.033257
C19: ='Datos Inic'!B17 -> RQ | D19: ='Datos Inic'!L17 -> 0.35 | E19: ='Datos Inic'!C17 -> 224 | F19: ='Datos Inic'!H17/1000 -> 0.1004575 | G19: =+F19*4/(3.1415*D19^2) -> 1.0441652 | H19: =10.643*140^(-1.85)*D19^(-4.87)*ABS(F19)^1.85*IF(F19<0,-1,1) -> 0.002696393 | I19: =+H19*E19 -> 0.60399204 | J19: =+I19/F19 -> 6.0124136 | K19: =-I21/(J21*1.851) -> 0.044018 | M19: =+F19+K19+L19 -> 0.1444755
B20: I | C20: ='Datos Inic'!B18 -> GQ | D20: ='Datos Inic'!L18 -> 0.35 | E20: ='Datos Inic'!C18 -> 336 | F20: =-'Datos Inic'!H18/1000 -> -0.200915 | G20: =+F20*4/(3.1415*D20^2) -> -2.0883304 | H20: =10.643*140^(-1.85)*D20^(-4.87)*ABS(F20)^1.85*IF(F20<0,-1,1) -> -0.0097205019 | I20: =+H20*E20 -> -3.2660886 | J20: =+I20/F20 -> 16.256072 | K20: =-I21/(J21*1.851) -> 0.044018 | L20: =-K11 -> 0.01071584 | M20: =+F20+K20+L20 -> -0.14618116
H21: SUMA | I21: =+SUM(I17:I20) -> -4.7434064 | J21: =+SUM(J17:J20) -> 58.217508
A23: 2da iteración
A24: =A7 -> CIRCUITO | C24: =C7 -> TRAMO | D24: =D7 -> DIAM.(m) | E24: =E7 -> LONG.(m) | F24: CAUDAL (m3/s) | G24: VELOC.(m/s) | H24: J (m/m) | I24: Hi(m) | J24: Hi/Qi | K24: CORRECCIÓN | M24: CAUDAL (m3/s)
A25: =A8 -> PROPIO | B25: =B8 -> COMUN | K25: PROPIA | L25: COMUN
A26: =A9 -> I | C26: =C9 -> AB | D26: =D9 -> 0.2 | E26: =E9 -> 224 | F26: =M9 -> 0.01633041 | G26: =+F26*4/(3.1415*D26^2) -> 0.51982842 | H26: =10.643*140^(-1.85)*D26^(-4.87)*ABS(F26)^1.85*IF(F26<0,-1,1) -> 0.0014280905 | I26: =+H26*E26 -> 0.31989226 | J26: =+I26/F26 -> 19.588747 | K26: =-I30/(J30*1.851) -> 0.0018802528 | M26: =+F26+K26+L26 -> 0.018210663
C27: =C10 -> RB | D27: =D10 -> 0.3 | E27: =E10 -> 336 | F27: =M10 -> -0.08799084 | G27: =+F27*4/(3.1415*D27^2) -> -1.2448525 | H27: =10.643*140^(-1.85)*D27^(-4.87)*ABS(F27)^1.85*IF(F27<0,-1,1) -> -0.0044704989 | I27: =+H27*E27 -> -1.5020876 | J27: =+I27/F27 -> 17.070955 | K27: =-I30/(J30*1.851) -> 0.0018802528 | M27: =+F27+K27+L27 -> -0.086110587
B28: =B11 -> II | C28: =C11 -> RQ | D28: =D11 -> 0.35 | E28: =E11 -> 224 | F28: =M11 -> 0.04572366 | G28: =+F28*4/(3.1415*D28^2) -> 0.47525623 | H28: =10.643*140^(-1.85)*D28^(-4.87)*ABS(F28)^1.85*IF(F28<0,-1,1) -> 0.00062860328 | I28: =+H28*E28 -> 0.14080713 | J28: =+I28/F28 -> 3.0795246 | K28: =-I30/(J30*1.851) -> 0.0018802528 | L28: =-K37 -> -0.014856872 | M28: =+F28+K28+L28 -> 0.03274704
C29: =C12 -> QA | D29: =D12 -> 0.25 | E29: =E12 -> 336 | F29: =M12 -> 0.03951291 | G29: =+F29*4/(3.1415*D29^2) -> 0.80497413 | H29: =10.643*140^(-1.85)*D29^(-4.87)*ABS(F29)^1.85*IF(F29<0,-1,1) -> 0.0024701682 | I29: =+H29*E29 -> 0.82997652 | J29: =+I29/F29 -> 21.005199 | K29: =-I30/(J30*1.851) -> 0.0018802528 | M29: =+F29+K29+L29 -> 0.041393163
H30: SUMA | I30: =+SUM(I26:I29) -> -0.21141173 | J30: =+SUM(J26:J29) -> 60.744425
A32: =A15 -> CIRCUITO | C32: =C15 -> TRAMO | D32: =D15 -> DIAM.(m) | E32: =E15 -> LONG.(m) | F32: CAUDAL (m3/s) | G32: VELOC.(m/s) | H32: J (m/m) | I32: Hi(m) | J32: Hi/Qi | K32: CORRECCIÓN | M32: CAUDAL (m3/s)
A33: =A16 -> PROPIO | B33: =B16 -> COMUN | K33: PROPIA | L33: COMUN
A34: =A17 -> II | C34: =C17 -> HR | D34: =D17 -> 0.25 | E34: =E17 -> 336 | F34: =M17 -> -0.0062107499 | G34: =+F34*4/(3.1415*D34^2) -> -0.12652809 | H34: =10.643*140^(-1.85)*D34^(-4.87)*ABS(F34)^1.85*IF(F34<0,-1,1) -> -8.0551907e-05 | I34: =+H34*E34 -> -0.027065441 | J34: =+I34/F34 -> 4.3578378 | K34: =-I38/(J38*1.851) -> 0.014856872 | M34: =+F34+K34+L34 -> 0.008646122
C35: =C18 -> GH | D35: =D18 -> 0.3 | E35: =E18 -> 224 | F35: =M18 -> -0.033257 | G35: =+F35*4/(3.1415*D35^2) -> -0.47050418 | H35: =10.643*140^(-1.85)*D35^(-4.87)*ABS(F35)^1.85*IF(F35<0,-1,1) -> -0.00073897605 | I35: =+H35*E35 -> -0.16553064 | J35: =+I35/F35 -> 4.9773171 | K35: =-I38/(J38*1.851) -> 0.014856872 | M35: =+F35+K35+L35 -> -0.018400128
C36: =C19 -> RQ | D36: =D19 -> 0.35 | E36: =E19 -> 224 | F36: =M19 -> 0.1444755 | G36: =+F36*4/(3.1415*D36^2) -> 1.5016926 | H36: =10.643*140^(-1.85)*D36^(-4.87)*ABS(F36)^1.85*IF(F36<0,-1,1) -> 0.0052812302 | I36: =+H36*E36 -> 1.1829956 | J36: =+I36/F36 -> 8.1882089 | K36: =-I38/(J38*1.851) -> 0.014856872 | M36: =+F36+K36+L36 -> 0.15933237
B37: =B20 -> I | C37: =C20 -> GQ | D37: =D20 -> 0.35 | E37: =E20 -> 336 | F37: =M20 -> -0.14618116 | G37: =+F37*4/(3.1415*D37^2) -> -1.5194214 | H37: =10.643*140^(-1.85)*D37^(-4.87)*ABS(F37)^1.85*IF(F37<0,-1,1) -> -0.0053971553 | I37: =+H37*E37 -> -1.8134442 | J37: =+I37/F37 -> 12.405458 | K37: =-I38/(J38*1.851) -> 0.014856872 | L37: =-K28 -> -0.0018802528 | M37: =+F37+K37+L37 -> -0.13320454
H38: SUMA | I38: =+SUM(I34:I37) -> -0.82304468 | J38: =+SUM(J34:J37) -> 29.928822
A40: 3ra iteración
A41: =A7 -> CIRCUITO | C41: =C7 -> TRAMO | D41: =D7 -> DIAM.(m) | E41: =E7 -> LONG.(m) | F41: CAUDAL (m3/s) | G41: VELOC.(m/s) | H41: J (m/m) | I41: Hi(m) | J41: Hi/Qi | K41: CORRECCIÓN | M41: CAUDAL (m3/s)
A42: =A8 -> PROPIO | B42: =B8 -> COMUN | K42: PROPIA | L42: COMUN
A43: =A9 -> I | C43: =C9 -> AB | D43: =D9 -> 0.2 | E43: =E9 -> 224 | F43: =M26 -> 0.018210663 | G43: =+F43*4/(3.1415*D43^2) -> 0.57968049 | H43: =10.643*140^(-1.85)*D43^(-4.87)*ABS(F43)^1.85*IF(F43<0,-1,1) -> 0.0017470838 | I43: =+H43*E43 -> 0.39134678 | J43: =+I43/F43 -> 21.48998 | K43: =-I47/(J47*1.851) -> 0.0006183943 | M43: =+F43+K43+L43 -> 0.018829057
C44: =C10 -> RB | D44: =D10 -> 0.3 | E44: =E10 -> 336 | F44: =M27 -> -0.086110587 | G44: =+F44*4/(3.1415*D44^2) -> -1.2182515 | H44: =10.643*140^(-1.85)*D44^(-4.87)*ABS(F44)^1.85*IF(F44<0,-1,1) -> -0.0042953772 | I44: =+H44*E44 -> -1.4432467 | J44: =+I44/F44 -> 16.760387 | K44: =-I47/(J47*1.851) -> 0.0006183943 | M44: =+F44+K44+L44 -> -0.085492193
B45: =B11 -> II | C45: =C11 -> RQ | D45: =D11 -> 0.35 | E45: =E11 -> 224 | F45: =M28 -> 0.03274704 | G45: =+F45*4/(3.1415*D45^2) -> 0.34037597 | H45: =10.643*140^(-1.85)*D45^(-4.87)*ABS(F45)^1.85*IF(F45<0,-1,1) -> 0.00033898784 | I45: =+H45*E45 -> 0.075933277 | J45: =+I45/F45 -> 2.3187829 | K45: =-I47/(J47*1.851) -> 0.0006183943 | L45: =-K54 -> -0.0021232732 | M45: =+F45+K45+L45 -> 0.031242162
C46: =C12 -> QA | D46: =D12 -> 0.25 | E46: =E12 -> 336 | F46: =M29 -> 0.041393163 | G46: =+F46*4/(3.1415*D46^2) -> 0.84327945 | H46: =10.643*140^(-1.85)*D46^(-4.87)*ABS(F46)^1.85*IF(F46<0,-1,1) -> 0.0026920138 | I46: =+H46*E46 -> 0.90451663 | J46: =+I46/F46 -> 21.851837 | K46: =-I47/(J47*1.851) -> 0.0006183943 | M46: =+F46+K46+L46 -> 0.042011557
H47: SUMA | I47: =+SUM(I43:I46) -> -0.071450048 | J47: =+SUM(J43:J46) -> 62.420987
A49: =A15 -> CIRCUITO | C49: =C15 -> TRAMO | D49: =D15 -> DIAM.(m) | E49: =E15 -> LONG.(m) | F49: CAUDAL (m3/s) | G49: VELOC.(m/s) | H49: J (m/m) | I49: Hi(m) | J49: Hi/Qi | K49: CORRECCIÓN | M49: CAUDAL (m3/s)
...

Sheet Datos Inic
A1: 5- DATOS INICIALES
A2: MALLAS "I" Y "II"
A3: Cantidad de edificios | C3: =+'DATOS Y SISTEMA IMPULSIÓN RÍO'!B3*'DATOS Y SISTEMA IMPULSIÓN RÍO'!B4 -> 72 | D3: lotes | E3: =+C3/12 -> 6
A4: Caudal por edificios | C4: =+C5/C3 -> 2.1465278 | D4: l/s/lote | G4: 20
A5: Caudal medio diario= | C5: =+'DATOS Y SISTEMA IMPULSIÓN RÍO'!B17 -> 154.55 | D5: l/s = | K5: K1 = | L5: =+'DATOS Y SISTEMA IMPULSIÓN RÍO'!B20 -> 1.2
A6: Caudal maximo diario= | C6: =L5*C5 -> 185.46 | D6: l/s = | E6: =+(C6*3600*2)/(1000)+90 -> 1425.312 | F6: m3 por hora | G6: =E6/(PI()*(G4/2)^2) -> 4.536909 | J6: =+G7+0.3 -> 6.9621241 | K6: K2 = | L6: =+'DATOS Y SISTEMA IMPULSIÓN RÍO'!B21 -> 1.5
A7: Caudal maximo horario= | C7: =ROUND(L6*C6,3) -> 278.19 | D7: l/s = | E7: =+(C7*3600*2)/(1000)+90 -> 2092.968 | F7: m3 por hora | G7: =E7/(PI()*(G4/2)^2) -> 6.6621241
A8: Diferencia para cubrir solo hora pico = | E8: =+E7-E6 -> 667.656 | F8: m3 por hora | G8: =E8/(PI()*(G4/2)^2) -> 2.1252151 | H8: Altura de la base del tanque = | J8: =Presiones!J16 -> 10.46
A9: Por Zonas de Presión | M9: DG= | N9: =+$C$7-G16-G18 -> 0 | O9: =+$C$7-H16-H18 -> 0
A10: Anillo | B10: Tramo | C10: Long (m) | D10: Nº de lotes por tramo | E10: Qa (l/s) | F10: Qc (l/s) | G10: Qt (l/s) | H10: Qcorr (l/s) | I10: Diam recomendado (mm) | J10: Diam comercial (mm) | K10: Diam adop (mm) | L10: Diam (m) | M10: V (m/s) ≥ 0,6
A11: I | B11: AB | C11: =11+100+12+100+1 -> 224 | D11: 7 | E11: =D11*$C$4*$L$5*$L$6 -> 27.04625 | F11: 0 | G11: =+E11+F11 -> 27.04625 | H11: =+G11 -> 27.04625 | I11: =+SQRT((4*H11/1000)/(3.14*1.2))*1000 -> 169.44473 | J11: =+IF(I11<=200,200,IF(I11<=250,250,IF(I11<=300,300,IF(I11<=350,350,350)))) -> 200 | K11: 200 | L11: =+K11/1000 -> 0.2 | M11: =(H11/1000)/((PI()*(K11/1000)^2)/4) -> 0.86090888 | N11: =IF((M11<=0.6),"DISMINUIR EL DIAMETRO ADOPTADO"," ")
B12: RB | C12: =11+100+12+100+12+100+1 -> 336 | D12: 13 | E12: =D12*$C$4*$L$5*$L$6 -> 50.22875 | F12: =+G11 -> 27.04625 | G12: =+E12+F12 -> 77.275 | H12: =+G12 -> 77.275 | I12: =+SQRT((4*H12/1000)/(3.14*1.2))*1000 -> 286.41388 | J12: =+IF(I12<=200,200,IF(I12<=250,250,IF(I12<=300,300,IF(I12<=350,350,350)))) -> 300 | K12: 300 | L12: =+K12/1000 -> 0.3 | M12: =(H12/1000)/((PI()*(K12/1000)^2)/4) -> 1.0932176 | N12: =IF((M12<=0.6),"DISMINUIR EL DIAMETRO ADOPTADO"," ")
B13: RQ | C13: =11+100+12+100+1 -> 224 | D13: 6 | E13: =D13*$C$4*$L$5*$L$6 -> 23.1825 | F13: =+G12 -> 77.275 | G13: =+E13+F13 -> 100.4575 | H13: =+G13 -> 100.4575 | I13: =+SQRT((4*H13/1000)/(3.14*1.2))*1000 -> 326.56206 | J13: =+IF(I13<=200,200,IF(I13<=250,250,IF(I13<=300,300,IF(I13<=350,350,350)))) -> 350 | K13: 350 | L13: =+K13/1000 -> 0.35 | M13: =(H13/1000)/((PI()*(K13/1000)^2)/4) -> 1.0441344 | N13: =IF((M13<=0.6),"DISMINUIR EL DIAMETRO ADOPTADO"," ")
B14: QA | C14: =11+100+12+100+12+100+1 -> 336 | D14: 13 | E14: =D14*$C$4*$L$5*$L$6 -> 50.22875 | F14: 0 | G14: =+E14+F14 -> 50.22875 | H14: =+G14 -> 50.22875 | I14: =+SQRT((4*H14/1000)/(3.14*1.2))*1000 -> 230.91425 | J14: =+IF(I14<=200,200,IF(I14<=250,250,IF(I14<=300,300,IF(I14<=350,350,350)))) -> 250 | K14: 250 | L14: =+K14/1000 -> 0.25 | M14: =(H14/1000)/((PI()*(K14/1000)^2)/4) -> 1.0232517 | N14: =IF((M14<=0.6),"DISMINUIR EL DIAMETRO ADOPTADO"," ")
A15: II | B15: HR | C15: =+C14 -> 336 | D15: =+D18 -> 13 | E15: =D15*$C$4*$L$5*$L$6 -> 50.22875 | F15: 0 | G15: =+E15+F15 -> 50.22875 | H15: =+G15 -> 50.22875 | I15: =+SQRT((4*H15/1000)/(3.14*1.2))*1000 -> 230.91425 | J15: =+IF(I15<=200,200,IF(I15<=250,250,IF(I15<=300,300,IF(I15<=350,350,350)))) -> 250 | K15: 250 | L15: =+K15/1000 -> 0.25 | M15: =(H15/1000)/((PI()*(K15/1000)^2)/4) -> 1.0232517 | N15: =IF((M15<=0.6),"DISMINUIR EL DIAMETRO ADOPTADO"," ")
B16: GH | C16: =+C11 -> 224 | D16: 7 | E16: =D16*$C$4*$L$5*$L$6 -> 27.04625 | F16: =+G15 -> 50.22875 | G16: =+E16+F16 -> 77.275 | H16: =+G16+$N$9*0.5 -> 77.275 | I16: =+SQRT((4*H16/1000)/(3.14*1.2))*1000 -> 286.41388 | J16: =+IF(I16<=200,200,IF(I16<=250,250,IF(I16<=300,300,IF(I16<=350,350,350)))) -> 300 | K16: 300 | L16: =+K16/1000 -> 0.3 | M16: =(H16/1000)/((PI()*(K16/1000)^2)/4) -> 1.0932176 | N16: =IF((M16<=0.6),"DISMINUIR EL DIAMETRO ADOPTADO"," ")
B17: RQ | C17: =+C16 -> 224 | D17: 0 | E17: =D17*$C$4*$L$5*$L$6 -> 0 | F17: =+F13 -> 77.275 | G17: =+G13 -> 100.4575 | H17: =+H13 -> 100.4575 | I17: =+SQRT((4*H17/1000)/(3.14*1.2))*1000 -> 326.56206 | J17: =+IF(I17<=200,200,IF(I17<=250,250,IF(I17<=300,300,IF(I17<=350,350,350)))) -> 350 | K17: 350 | L17: =+K17/1000 -> 0.35 | M17: =(H17/1000)/((PI()*(K17/1000)^2)/4) -> 1.0441344 | N17: =IF((M17<=0.6),"DISMINUIR EL DIAMETRO ADOPTADO"," ")
B18: GQ | C18: =+C12 -> 336 | D18: 13 | E18: =D18*$C$4*$L$5*$L$6 -> 50.22875 | F18: =G13+G14 -> 150.68625 | G18: =+E18+F18 -> 200.915 | H18: =+G18-$N$9*0.5 -> 200.915 | I18: =+I13 -> 326.56206 | J18: =+IF(I18<=200,200,IF(I18<=250,250,IF(I18<=300,300,IF(I18<=350,350,350)))) -> 350 | K18: 350 | L18: =+K18/1000 -> 0.35 | M18: =(H18/1000)/((PI()*(K18/1000)^2)/4) -> 2.0882688 | N18: =IF((M18<=0.6),"DISMINUIR EL DIAMETRO ADOPTADO"," ")
D19: =SUM(D11:D18) -> 72 | E19: =ROUND(SUM(E11:E18),3) -> 278.19 | F19: =+F14+F11 -> 0 | G19: =+G14+G11 -> 77.275 | H19: =+H14+H11 -> 77.275 | K19: Tubos PBA
C20: =+C4*86400 -> 185460 | D20: =+IF(D19=C3,"Verifica","Revisar") -> Verifica | E20: =+IF(ROUND(E19=C7,3),"Verifica","Revisar") -> Verifica | F20: =+F16+F18 -> 200.915 | G20: =ROUND(G16+G18,3) -> 278.19 | H20: =ROUND(H16+H18,3) -> 278.19 | K20: Adop (mm)
C21: Ubicación del tanque | D21: =K16 -> 300 | G21: =+IF(G20=C7,"Verifica","Revisar") -> Verifica | H21: =+IF(H20=C7,"Verifica","Revisar") -> Verifica
H22: =0.8*H20 -> 222.552 | K22: 50
K23: 65
D24: =K18 -> 350 | E24: =K15 -> 250 | K24: 75
K25: 100
K26: 150
G27: =N16 | I27: =N14 | K27: 200
K28: 250
F29: =K17 -> 350 | K29: 300
D30: =K14 -> 250 | E30: =K12 -> 300 | K30: 350
D34: =K11 -> 200

Sheet Presiones
A1: 6- PRESIONES
A2: VERIFICACIÓN DE PRESIONES | M2: AUXILIAR
A3: ANILLO | B3: TRAMO | C3: DIAMETRO (m) | D3: LONGITUD (m) | E3: Qcorregido (m3/s) | F3: J (m/m) | G3: H (m) | H3: Cota Piez m | I3: Cota Terr m | J3: Carga Dispon mca | M3: Qcorregido (m3/s)
A5: I | B5: A | C5: ='Datos Inic'!L11 -> 0.2 | D5: ='Datos Inic'!C11 -> 224 | E5: =+M5 -> 0.018910526 | F5: =10.643*140^(-1.85)*C5^(-4.87)*ABS(E5)^1.85*IF(E5<0,-1,1) -> 0.0018733236 | G5: =+F5*D5 -> 0.41962448 | H5: =+H6+G5 -> 105.07007 | I5: 94 | J5: =+H5-I5 -> 11.070075 | L5: Copiar | M5: =+Caudales!M94 -> 0.018910526 | N5: Caudales
B6: B | H6: =+H7 -> 104.65045 | I6: 92 | J6: =+H6-I6 -> 12.65045 | M6: =+Caudales!M95 -> -0.085410724
B7: B | C7: ='Datos Inic'!L12 -> 0.3 | D7: ='Datos Inic'!C12 -> 336 | E7: =+M6 -> -0.085410724 | F7: =10.643*140^(-1.85)*C7^(-4.87)*ABS(E7)^1.85*IF(E7<0,-1,1) -> -0.0042310156 | G7: =+F7*D7 -> -1.4216213 | H7: =+H8+G7 -> 104.65045 | I7: =+I6 -> 92 | J7: =+H7-I7 -> 12.65045 | M7: =+Caudales!M96 -> 0.031088768
B8: R | H8: =+H9 -> 106.07207 | I8: 94 | J8: =+H8-I8 -> 12.072072 | M8: =+Caudales!M97 -> 0.042093026
B9: R | C9: ='Datos Inic'!L13 -> 0.35 | D9: ='Datos Inic'!C13 -> 224 | E9: =+M7 -> 0.031088768 | F9: =10.643*140^(-1.85)*C9^(-4.87)*ABS(E9)^1.85*IF(E9<0,-1,1) -> 0.00030791605 | G9: =+F9*D9 -> 0.068973195 | H9: =+H10+G9 -> 106.07207 | I9: =+I8 -> 94 | J9: =+H9-I9 -> 12.072072
B10: Q | H10: =+H11 -> 106.0031 | I10: 96 | J10: =+H10-I10 -> 10.003098
B11: Q | C11: ='Datos Inic'!L14 -> 0.25 | D11: ='Datos Inic'!C14 -> 336 | E11: =+M8 -> 0.042093026 | F11: =10.643*140^(-1.85)*C11^(-4.87)*ABS(E11)^1.85*IF(E11<0,-1,1) -> 0.0027768226 | G11: =+F11*D11 -> 0.93301238 | H11: =+H18 -> 106.0031 | I11: =+I10 -> 96 | J11: =+H11-I11 -> 10.003098
B12: A | H12: =+H11-G11 -> 105.07009 | I12: =+I5 -> 94 | J12: =+H12-I12 -> 11.070086 | K12: =+SUM(G5:G12) -> -1.1205901e-05
A13: II | B13: R | C13: ='Datos Inic'!L15 -> 0.25 | D13: ='Datos Inic'!C15 -> 336 | E13: =+M14 -> 0.011004258 | F13: =10.643*140^(-1.85)*C13^(-4.87)*ABS(E13)^1.85*IF(E13<0,-1,1) -> 0.00023208482 | G13: =+F13*D13 -> 0.0779805 | H13: =+H14+G13 -> 107.49501 | I13: =+I8 -> 94 | J13: =+H13-I13 -> 13.495015
B14: H | H14: =+H15 -> 107.41703 | I14: 95 | J14: =+H14-I14 -> 12.417034 | L14: Copiar | M14: =Caudales!M102 -> 0.011004258 | N14: Caudales
B15: H | C15: ='Datos Inic'!L16 -> 0.3 | D15: ='Datos Inic'!C16 -> 224 | E15: =+M15 -> -0.016041992 | F15: =10.643*140^(-1.85)*C15^(-4.87)*ABS(E15)^1.85*IF(E15<0,-1,1) -> -0.00019181146 | G15: =+F15*D15 -> -0.042965767 | H15: =+H16+G15 -> 107.41703 | I15: =+I14 -> 95 | J15: =+H15-I15 -> 12.417034 | M15: =Caudales!M103 -> -0.016041992
B16: G | H16: =+I16+J16 -> 107.46 | I16: 97 | J16: 10.46 | K16: Ubicación y base del Tanque | M16: =Caudales!M104 -> 0.16169051
B17: G | C17: ='Datos Inic'!L17 -> 0.35 | D17: ='Datos Inic'!C17 -> 224 | E17: =+M16 -> 0.16169051 | F17: =10.643*140^(-1.85)*C17^(-4.87)*ABS(E17)^1.85*IF(E17<0,-1,1) -> 0.0065040248 | G17: =+F17*D17 -> 1.4569016 | H17: =+H16 -> 107.46 | I17: =+I16 -> 97 | J17: =+H17-I17 -> 10.46 | M17: =Caudales!M105 -> -0.13154627
B18: Q | H18: =+H17-G17 -> 106.0031 | I18: =+I10 -> 96 | J18: =+H18-I18 -> 10.003098
B19: Q | C19: ='Datos Inic'!L18 -> 0.35 | D19: ='Datos Inic'!C18 -> 336 | E19: =+M17 -> -0.13154627 | F19: =10.643*140^(-1.85)*C19^(-4.87)*ABS(E19)^1.85*IF(E19<0,-1,1) -> -0.0044402877 | G19: =+F19*D19 -> -1.4919367 | H19: =+H18 -> 106.0031 | I19: =+I18 -> 96 | J19: =+H19-I19 -> 10.003098
B20: R | H20: =+H19-G19 -> 107.49504 | I20: =+I8 -> 94 | J20: =+H20-I20 -> 13.495035 | K20: =+SUM(G13:G20) -> -2.0358144e-05
B21: CORREGIR EN LA ITERACION SELECCIONADA | I21: MÁXIMO | J21: =+MAX(J5:J20) -> 13.495035
I22: MÍNIMO | J22: =+MIN(J5:J20) -> 10.003098 | K22: >=10
I23: Perdida= | J23: =+J21-J22 -> 3.4919367
I24: VERIFICACIÓN DE LA PRESION MÍNIMA PERMITIDA: | J24: =+IF(J22>=10,"VERIFICA","NO VERIFICA") -> VERIFICA
D26: Ubicación del tanque
D27: =I16 -> 97 | G27: =I14 -> 95
D33: =I10 -> 96 | G33: =I8 -> 94
D39: =I5 -> 94 | G39: =I6 -> 92

Sheet RED CLOACAL
A1: 7- RED CLOACAL
A3: DESAGUE CLOACAL
A4: Valores adoptados para el cálculo
A5: Caudal por edificios | B5: ='Datos Inic'!C4 -> 2.1465278 | C5: l/s/lote
A6: Coeficiente de retorno (80 a 90%) | B6: 80 | C6: %
A7: K1 = | B7: ='Datos Inic'!L5 -> 1.2
A8: K2 = | B8: ='Datos Inic'!L6 -> 1.5
A9: Longitud total de la red | B9: =+SUM(C24:C98) -> 4084 | C9: m
A10: Caudal maximo por edificios | B10: =+B5*B6/100*B7*B8 -> 3.091 | C10: l/s/lote
A11: Tasa de infiltración | B11: 0.05 | C11: l/s/km
A12: Caudal máximo | B12: =(F94+E94)/1000 -> 0.2351202 | C12: m3/s
B13: =B12*1000 -> 235.1202 | C13: l/s
A14: Velocidad minima | B14: 0.6 | C14: m/s
A15: Velocidad máxima | B15: 5 | C15: m/s
A16: Formula de Bazin | B16: v=(87/(1+(γ/(√RH)))*(√RH*I)
A17: RH | B17: Radio hidráulico
A18: Valor del coeficiente γ, | B18: 0.22
A19: Coeficiente de escurrimiento | B19: 0.95
A20: PROFUNDIDAD DEL TUBO DEL REGISTRO MAS ALEJADO | B20: =1.2+R24 -> 1.45 | C20: m
A21: http://www.bvsde.paho.org/tecapro/documentos/sanea/169esp-diseno-alcantar.pdf
A23: Tramo | B23: Nº de lotes | C23: Longitud del tramo (m) | D23: Caudal del tramo (l/s) | E23: Caudal acumulado (l/s) | F23: Caudal de inflitración (l/s) | G23: Caudal mìnima (l/s) | H23: Pend. minima (%) | I23: Pend. adoptada (%) | J23: Descenso de tubería (m) | K23: Cota del Terreno sobre Registro a Entrada al Tramo | L23: Cota del Terreno sobre Registro a Salida del Tramo | M23: Cota de Fondo del Registro a Entrada al Tramo | N23: Cota de Fondo del Registro a Salida del Tramo | O23: Profundidad del Registro de Entrada (m) | P23: Prof. Min: 1,2 m | Q23: Profundidad del Registro de Salida (m) | R23: Diámetro de Tubería requerido (m) | S23: Radio Hidráulico (RH) | T23: Velocidad (m/seg) | U23: V.min.: 0,6 m/s | V23: V. max.: 5 m/s | W23: Caudal que podrá conducir (m3/s) | X23: Caudal obtenido a traves el área de escurrimiento (m3/s) | Y23: Verificación de caudales
A24: T7-6 | B24: 2 | C24: 112 | D24: =B24*$B$10 -> 6.182 | E24: =+D24 -> 6.182 | F24: =+$B$11*C24/1000 -> 0.0056 | G24: =+IF((E24+F24)>1.5,(E24+F24),1.5) -> 6.1876 | H24: =(0.0055*(G24^-0.47))*100 -> 0.23353245 | I24: 0.5 | J24: =C24*(I24/100) -> 0.56 | K24: 97 | L24: =+K25 -> 96.666667 | M24: =+K24-$B$20 -> 95.55 | N24: =+M24-J24 -> 94.99 | O24: =K24-M24 -> 1.45 | P24: =IF((K24-M24)>=1.2,"verifica","aumentar pendiente") -> verifica | Q24: =L24-N24 -> 1.6766667 | R24: 0.25 | S24: =R24/4 -> 0.0625 | T24: =(87/(1+(0.14/S24^(1/2))))*(S24*(I24/100))^(1/2) -> 0.98587003 | U24: =IF(T24>=$B$14,"verifica", "aumentar diámetro") -> verifica | V24: =IF(T24<=$B$15,"verifica","disminuir pend.") -> verifica | W24: =(3.14*(R24/2)^2*T24) -> 0.048369248 | X24: =(E24+F24)/1000 -> 0.0061876 | Y24: =IF(W24>=X24,"verifica","no verifica") -> verifica
A25: T6-5 | B25: 2 | C25: 112 | D25: =B25*$B$10 -> 6.182 | E25: =+E24+D25 -> 12.364 | F25: =+$B$11*C25/1000+F24 -> 0.0112 | G25: =+IF((E25+F25)>1.5,(E25+F25),1.5) -> 12.3752 | H25: =(0.0055*(G25^-0.47))*100 -> 0.16860216 | I25: 0.5 | J25: =C25*(I25/100) -> 0.56 | K25: =K24-(K24-K27)/(C24*3)*C24 -> 96.666667 | L25: =+K26 -> 96.333333 | M25: =+N24 -> 94.99 | N25: =+M25-J25 -> 94.43 | O25: =K25-M25 -> 1.6766667 | P25: =IF((K25-M25)>=1.2,"verifica","aumentar pendiente") -> verifica | Q25: =L25-N25 -> 1.9033333 | R25: 0.25 | S25: =R25/4 -> 0.0625 | T25: =(87/(1+(0.14/S25^(1/2))))*(S25*(I25/100))^(1/2) -> 0.98587003 | U25: =IF(T25>=$B$14,"verifica", "aumentar diámetro") -> verifica | V25: =IF(T25<=$B$15,"verifica","disminuir pend.") -> verifica | W25: =(3.14*(R25/2)^2*T25) -> 0.048369248 | X25: =(E25+F25)/1000 -> 0.0123752 | Y25: =IF(W25>=X25,"verifica","no verifica") -> verifica
A26: T5-4 | B26: 2 | C26: 112 | D26: =B26*$B$10 -> 6.182 | E26: =+E25+D26 -> 18.546 | F26: =+$B$11*C26/1000+F25 -> 0.0168 | G26: =+IF((E26+F26)>1.5,(E26+F26),1.5) -> 18.5628 | H26: =(0.0055*(G26^-0.47))*100 -> 0.13934784 | I26: 0.5 | J26: =C26*(I26/100) -> 0.56 | K26: =K24-(K24-K27)/(C24*3)*C24*2 -> 96.333333 | L26: =+K27 -> 96 | M26: =+N25 -> 94.43 | N26: =+M26-J26 -> 93.87 | O26: =K26-M26 -> 1.9033333 | P26: =IF((K26-M26)>=1.2,"verifica","aumentar pendiente") -> verifica | Q26: =L26-N26 -> 2.13 | R26: 0.25 | S26: =R26/4 -> 0.0625 | T26: =(87/(1+(0.14/S26^(1/2))))*(S26*(I26/100))^(1/2) -> 0.98587003 | U26: =IF(T26>=$B$14,"verifica", "aumentar diámetro") -> verifica | V26: =IF(T26<=$B$15,"verifica","disminuir pend.") -> verifica | W26: =(3.14*(R26/2)^2*T26) -> 0.048369248 | X26: =(E26+F26)/1000 -> 0.0185628 | Y26: =IF(W26>=X26,"verifica","no verifica") -> verifica
A27: T4-3 | B27: 2 | C27: 112 | D27: =B27*$B$10 -> 6.182 | E27: =+E26+D27 -> 24.728 | F27: =+$B$11*C27/1000+F25 -> 0.0168 | G27: =+IF((E27+F27)>1.5,(E27+F27),1.5) -> 24.7448 | H27: =(0.0055*(G27^-0.47))*100 -> 0.12173774 | I27: 0.5 | J27: =C27*(I27/100) -> 0.56 | K27: 96 | L27: =+K28 -> 95.333333 | M27: =+N26 -> 93.87 | N27: =+M27-J27 -> 93.31 | O27: =K27-M27 -> 2.13 | P27: =IF((K27-M27)>=1.2,"verifica","aumentar pendiente") -> verifica | Q27: =L27-N27 -> 2.0233333 | R27: 0.25 | S27: =R27/4 -> 0.0625 | T27: =(87/(1+(0.14/S27^(1/2))))*(S27*(I27/100))^(1/2) -> 0.98587003 | U27: =IF(T27>=$B$14,"verifica", "aumentar diámetro") -> verifica | V27: =IF(T27<=$B$15,"verifica","disminuir pend.") -> verifica | W27: =(3.14*(R27/2)^2*T27) -> 0.048369248 | X27: =(E27+F27)/1000 -> 0.0247448 | Y27: =IF(W27>=X27,"verifica","no verifica") -> verifica
A28: T3-2 | B28: 2 | C28: 112 | D28: =B28*$B$10 -> 6.182 | E28: =+E27+D28 -> 30.91 | F28: =+$B$11*C28/1000+F26 -> 0.0224 | G28: =+IF((E28+F28)>1.5,(E28+F28),1.5) -> 30.9324 | H28: =(0.0055*(G28^-0.47))*100 -> 0.10961457 | I28: 0.5 | J28: =C28*(I28/100) -> 0.56 | K28: =K27-(K27-K30)/(C28*3)*C24 -> 95.333333 | L28: =+K29 -> 94.666667 | M28: =+N27 -> 93.31 | N28: =+M28-J28 -> 92.75 | O28: =K28-M28 -> 2.0233333 | P28: =IF((K28-M28)>=1.2,"verifica","aumentar pendiente") -> verifica | Q28: =L28-N28 -> 1.9166667 | R28: 0.25 | S28: =R28/4 -> 0.0625 | T28: =(87/(1+(0.14/S28^(1/2))))*(S28*(I28/100))^(1/2) -> 0.98587003 | U28: =IF(T28>=$B$14,"verifica", "aumentar diámetro") -> verifica | V28: =IF(T28<=$B$15,"verifica","disminuir pend.") -> verifica | W28: =(3.14*(R28/2)^2*T28) -> 0.048369248 | X28: =(E28+F28)/1000 -> 0.0309324 | Y28: =IF(W28>=X28,"verifica","no verifica") -> verifica
A29: T2-1 | B29: 2 | C29: 112 | D29: =B29*$B$10 -> 6.182 | E29: =+E28+D29 -> 37.092 | F29: =+$B$11*C29/1000+F27 -> 0.0224 | G29: =+IF((E29+F29)>1.5,(E29+F29),1.5) -> 37.1144 | H29: =(0.0055*(G29^-0.47))*100 -> 0.10061848 | I29: 0.5 | J29: =C29*(I29/100) -> 0.56 | K29: =K28-(K27-K30)/(C29*3)*C28 -> 94.666667 | L29: =+K30 -> 94 | M29: =+N28 -> 92.75 | N29: =+M29-J29 -> 92.19 | O29: =K29-M29 -> 1.9166667 | P29: =IF((K29-M29)>=1.2,"verifica","aumentar pendiente") -> verifica | Q29: =L29-N29 -> 1.81 | R29: 0.25 | S29: =R29/4 -> 0.0625 | T29: =(87/(1+(0.14/S29^(1/2))))*(S29*(I29/100))^(1/2) -> 0.98587003 | U29: =IF(T29>=$B$14,"verifica", "aumentar diámetro") -> verifica | V29: =IF(T29<=$B$15,"verifica","disminuir pend.") -> verifica | W29: =(3.14*(R29/2)^2*T29) -> 0.048369248 | X29: =(E29+F29)/1000 -> 0.0371144 | Y29: =IF(W29>=X29,"verifica","no verifica") -> verifica
A30: T1-11 | B30: 1 | C30: 112 | D30: =B30*$B$10 -> 3.091 | E30: =+E29+D30 -> 40.183 | F30: =+$B$11*C30/1000+F29 -> 0.028 | G30: =+IF((E30+F30)>1.5,(E30+F30),1.5) -> 40.211 | H30: =(0.0055*(G30^-0.47))*100 -> 0.096899291 | I30: 0.5 | J30: =C30*(I30/100) -> 0.56 | K30: 94 | L30: =+K31 -> 93 | M30: =+N29 -> 92.19 | N30: =+M30-J30 -> 91.63 | O30: =K30-M30 -> 1.81 | P30: =IF((K30-M30)>=1.2,"verifica","aumentar pendiente") -> verifica | Q30: =L30-N30 -> 1.37 | R30: 0.25 | S30: =R30/4 -> 0.0625 | T30: =(87/(1+(0.14/S30^(1/2))))*(S30*(I30/100))^(1/2) -> 0.98587003 | U30: =IF(T30>=$B$14,"verifica", "aumentar diámetro") -> verifica | V30: =IF(T30<=$B$15,"verifica","disminuir pend.") -> verifica | W30: =(3.14*(R30/2)^2*T30) -> 0.048369248 | X30: =(E30+F30)/1000 -> 0.040211 | Y30: =IF(W30>=X30,"verifica","no verifica") -> verifica
A31: 11 | K31: =+(K30+K89)/2 -> 93 | M31: =+N30 -> 91.63 | O31: =K31-M31 -> 1.37
A35: T7-17 | B35: 1 | C35: 112 | D35: =B35*$B$10 -> 3.091 | E35: =+D35 -> 3.091 | F35: =+$B$11*C35/1000 -> 0.0056 | G35: =+IF((E35+F35)>1.5,(E35+F35),1.5) -> 3.0966 | H35: =(0.0055*(G35^-0.47))*100 -> 0.32333051 | I35: 0.7 | J35: =C35*(I35/100) -> 0.784 | K35: =+K24 -> 97 | L35: =+K36 -> 96 | M35: =+K35-$B$20 -> 95.55 | N35: =+M35-J35 -> 94.766 | O35: =K35-M35 -> 1.45 | P35: =IF((K35-M35)>=1.2,"verifica","aumentar pendiente") -> verifica | Q35: =L35-N35 -> 1.234 | R35: 0.15 | S35: =R35/4 -> 0.0375 | T35: =(87/(1+(0.14/S35^(1/2))))*(S35*(I35/100))^(1/2) -> 0.81810584 | U35: =IF(T35>=$B$14,"verifica", "aumentar diámetro") -> verifica | V35: =IF(T35<=$B$15,"verifica","disminuir pend.") -> verifica | W35: =(3.14*(R35/2)^2*T35) -> 0.014449794 | X35: =(E35+F35)/1000 -> 0.0030966 | Y35: =IF(W35>=X35,"verifica","no verifica") -> verifica
A36: 17 | K36: =+(K35+K83)/2 -> 96 | M36: =+N35 -> 94.766 | O36: =K36-M36 -> 1.234 | P36: =IF((K36-M36)>=1.2,"verifica","aumentar pendiente") -> verifica
A38: T6-16 | B38: 2 | C38: 112 | D38: =B38*$B$10 -> 6.182 | E38: =+D38 -> 6.182 | F38: =+$B$11*C38/1000 -> 0.0056 | G38: =+IF((E38+F38)>1.5,(E38+F38),1.5) -> 6.1876 | H38: =(0.0055*(G38^-0.47))*100 -> 0.23353245 | I38: 0.7 | J38: =C38*(I38/100) -> 0.784 | K38: =+K25 -> 96.666667 | L38: =+K39 -> 95.666667 | M38: =+K38-$B$20 -> 95.216667 | N38: =+M38-J38 -> 94.432667 | O38: =K38-M38 -> 1.45 | P38: =IF((K38-M38)>=1.2,"verifica","aumentar pendiente") -> verifica | Q38: =L38-N38 -> 1.234 | R38: 0.15 | S38: =R38/4 -> 0.0375 | T38: =(87/(1+(0.14/S38^(1/2))))*(S38*(I38/100))^(1/2) -> 0.81810584 | U38: =IF(T38>=$B$14,"verifica", "aumentar diámetro") -> verifica | V38: =IF(T38<=$B$15,"verifica","disminuir pend.") -> verifica | W38: =(3.14*(R38/2)^2*T38) -> 0.014449794 | X38: =(E38+F38)/1000 -> 0.0061876 | Y38: =IF(W38>=X38,"verifica","no verifica") -> verifica
A39: 16 | K39: =+(K25+K84)/2 -> 95.666667 | M39: =+N38 -> 94.432667 | O39: =K39-M39 -> 1.234 | P39: =IF((K39-M39)>=1.2,"verifica","aumentar pendiente") -> verifica
A41: T5-15 | B41: 2 | C41: 112 | D41: =B41*$B$10 -> 6.182 | E41: =+D41 -> 6.182 | F41: =+$B$11*C41/1000 -> 0.0056 | G41: =+IF((E41+F41)>1.5,(E41+F41),1.5) -> 6.1876 | H41: =(0.0055*(G41^-0.47))*100 -> 0.23353245 | I41: 0.7 | J41: =C41*(I41/100) -> 0.784 | K41: =+K26 -> 96.333333 | L41: =+K42 -> 95.388889 | M41: =+K41-$B$20 -> 94.883333 | N41: =+M41-J41 -> 94.099333 | O41: =K41-M41 -> 1.45 | P41: =IF((K41-M41)>=1.2,"verifica","aumentar pendiente") -> verifica | Q41: =L41-N41 -> 1.2895556 | R41: 0.15 | S41: =R41/4 -> 0.0375 | T41: =(87/(1+(0.14/S41^(1/2))))*(S41*(I41/100))^(1/2) -> 0.81810584 | U41: =IF(T41>=$B$14,"verifica", "aumentar diámetro") -> verifica | V41: =IF(T41<=$B$15,"verifica","disminuir pend.") -> verifica | W41: =(3.14*(R41/2)^2*T41) -> 0.014449794 | X41: =(E41+F41)/1000 -> 0.0061876 | Y41: =IF(W41>=X41,"verifica","no verifica") -> verifica
A42: 15 | K42: =+(K26+K85)/2 -> 95.388889 | M42: =+N41 -> 94.099333 | O42: =K42-M42 -> 1.2895556 | P42: =IF((K42-M42)>=1.2,"verifica","aumentar pendiente") -> verifica
A44: T4-14 | B44: 2 | C44: 112 | D44: =B44*$B$10 -> 6.182 | E44: =+D44 -> 6.182 | F44: =+$B$11*C44/1000 -> 0.0056 | G44: =+IF((E44+F44)>1.5,(E44+F44),1.5) -> 6.1876 | H44: =(0.0055*(G44^-0.47))*100 -> 0.23353245 | I44: 0.7 | J44: =C44*(I44/100) -> 0.784 | K44: =+K27 -> 96 | L44: =+K45 -> 95 | M44: =+K44-$B$20 -> 94.55 | N44: =+M44-J44 -> 93.766 | O44: =K44-M44 -> 1.45 | P44: =IF((K44-M44)>=1.2,"verifica","aumentar pendiente") -> verifica | Q44: =L44-N44 -> 1.234 | R44: 0.15 | S44: =R44/4 -> 0.0375 | T44: =(87/(1+(0.14/S44^(1/2))))*(S44*(I44/100))^(1/2) -> 0.81810584 | U44: =IF(T44>=$B$14,"verifica", "aumentar diámetro") -> verifica | V44: =IF(T44<=$B$15,"verifica","disminuir pend.") -> verifica | W44: =(3.14*(R44/2)^2*T44) -> 0.014449794 | X44: =(E44+F44)/1000 -> 0.0061876 | Y44: =IF(W44>=X44,"verifica","no verifica") -> verifica
A45: 14 | K45: =+(K27+K86)/2 -> 95 | M45: =+N44 -> 93.766 | O45: =K45-M45 -> 1.234 | P45: =IF((K45-M45)>=1.2,"verifica","aumentar pendiente") -> verifica
A47: T3-13 | B47: 2 | C47: 112 | D47: =B47*$B$10 -> 6.182 | E47: =+D47 -> 6.182 | F47: =+$B$11*C47/1000 -> 0.0056 | G47: =+IF((E47+F47)>1.5,(E47+F47),1.5) -> 6.1876 | H47: =(0.0055*(G47^-0.47))*100 -> 0.23353245 | I47: 2 | J47: =C47*(I47/100) -> 2.24 | K47: =+K28 -> 95.333333 | L47: =+K48 -> 93.333333 | M47: =+K47-$B$20 -> 93.883333 | N47: =+M47-J47 -> 91.643333 | O47: =K47-M47 -> 1.45 | P47: =IF((K47-M47)>=1.2,"verifica","aumentar pendiente") -> verifica | Q47: =L47-N47 -> 1.69 | R47: 0.1 | S47: =R47/4 -> 0.025 | T47: =(87/(1+(0.14/S47^(1/2))))*(S47*(I47/100))^(1/2) -> 1.0317918 | U47: =IF(T47>=$B$14,"verifica", "aumentar diámetro") -> verifica | V47: =IF(T47<=$B$15,"verifica","disminuir pend.") -> verifica | W47: =(3.14*(R47/2)^2*T47) -> 0.0080995654 | X47: =(E47+F47)/1000 -> 0.0061876 | Y47: =IF(W47>=X47,"verifica","no verifica") -> verifica
A48: 13 | K48: =+K87 -> 93.333333 | M48: =+N47 -> 91.643333 | O48: =K48-M48 -> 1.69 | P48: =IF((K48-M48)>=1.2,"verifica","aumentar pendiente") -> verifica
A50: T2-12 | B50: 2 | C50: 112 | D50: =B50*$B$10 -> 6.182 | E50: =+D50 -> 6.182 | F50: =+$B$11*C50/1000 -> 0.0056 | G50: =+IF((E50+F50)>1.5,(E50+F50),1.5) -> 6.1876 | H50: =(0.0055*(G50^-0.47))*100 -> 0.23353245 | I50: 2 | J50: =C50*(I50/100) -> 2.24 | K50: =+K29 -> 94.666667 | L50: =+K51 -> 92.888889 | M50: =+K50-$B$20 -> 93.216667 | N50: =+M50-J50 -> 90.976667 | O50: =K50-M50 -> 1.45 | P50: =IF((K50-M50)>=1.2,"verifica","aumentar pendiente") -> verifica | Q50: =L50-N50 -> 1.9122222 | R50: 0.1 | S50: =R50/4 -> 0.025 | T50: =(87/(1+(0.14/S50^(1/2))))*(S50*(I50/100))^(1/2) -> 1.0317918 | U50: =IF(T50>=$B$14,"verifica", "aumentar diámetro") -> verifica | V50: =IF(T50<=$B$15,"verifica","disminuir pend.") -> verifica | W50: =(3.14*(R50/2)^2*T50) -> 0.0080995654 | X50: =(E50+F50)/1000 -> 0.0061876 | Y50: =IF(W50>=X50,"verifica","no verifica") -> verifica
...

Sheet TRATAMIENTO PRELIMINAR
A1: 8- TRATAMIENTO PRELIMINAR
A3: Datos | B3: Valores | C3: Unidades
A4: Parametros de Cálculo
A5: Caudal Máximo | B5: ='RED CLOACAL'!G94/1000 -> 0.2351202 | C5: m3/s
A6: Caudal Medio | B6: =+B5/'RED CLOACAL'!B7/'RED CLOACAL'!B8 -> 0.13062233 | C6: m3/s
A7: Caudal Mínimo | B7: =+B6*0.5 -> 0.065311167 | C7: m3/s
A8: Caudal Máximo | B8: =+B5*1000 -> 235.1202 | C8: l/s
A9: Caudal Medio | B9: =+B6*1000 -> 130.62233 | C9: l/s
A10: Caudal Mínimo | B10: =+B7*1000 -> 65.311167 | C10: l/s
A12: Datos Constructivos
A13: Predimencsionado del ancho del canal
A14: - Con Q max. y velocidad de 0,3 m/s
A15: Se adopta un ancho de canal b = | B15: 2 | C15: m. | D15: Se prefiere más ancho que alto, se puede ir variando para obtener dimensiones constructivamente prácticas
A17: Cálculo de la lámina en el canal
A18: La altura de la lamina de agua en el tanque de arena resulta:
A19: - Para caudal maximo: H max = | B19: =+(((B5/0.3))/($B$15)) -> 0.391867 | C19: m.
A20: - Para caudal medio: H med.= | B20: =+(((B6/0.3))/($B$15)) -> 0.21770389 | C20: m.
A21: - Para caudal minimo: H min. = | B21: =+(((B7/0.3))/($B$15)) -> 0.10885194 | C21: m. | F21: Caudal (l/s) de Vertedores Parshall
A22: Inclinación de la reja | B22: 45 | C22: º | D22: 30 a 45° | F22: Altura H | G22: Ancho de la Garganta
A23: Grosor de las barras | B23: 0.3 | C23: cm | F23: (cm) | G23: 7,6 cm | H23: 15,2 cm | I23: 22,9 cm | J23: 30,5 cm
A24: Ancho de las barras | B24: 2.5 | C24: cm | F24: 3 | G24: 0.8 | H24: 1.4 | I24: 2.5 | J24: 3.1
A25: Esparcimiento entre barras | B25: 1 | C25: cm | F25: 4 | G25: 1.2 | H25: 2.3 | I25: 4 | J25: 4.6
A26: Velocidad de las aguas (0,40 a 0,75 m/s) | B26: 0.6 | C26: m/s | F26: 5 | G26: 1.5 | H26: 3.2 | I26: 5.5 | J26: 7
A27: Conclusiones sobre las rejas | F27: 6 | G27: 2.3 | H27: 4.5 | I27: 7.3 | J27: 9.9
A28: Area útil de las rejas | B28: =+B5/B26 -> 0.391867 | C28: m2 | F28: 7 | G28: 2.9 | H28: 5.7 | I28: 9.1 | J28: 12.5
A29: Eficiencia de las rejas | B29: =+B25/(B25+B23) -> 0.76923077 | F29: 8 | G29: 3.5 | H29: 7.1 | I29: 11.1 | J29: 14.5
A30: Sección de escurrimiento del canal | B30: =+B28/B29 -> 0.5094271 | C30: m2 | F30: 9 | G30: 4.3 | H30: 8.5 | I30: 13.5 | J30: 17.7
A31: Ancho del canal de rejas | B31: =+B30/(B19) -> 1.3 | C31: m | F31: 10 | G31: 5 | H31: 10.3 | I31: 15.8 | J31: 20.9
A32: Números de barras | B32: =+INT(B31/(B25/100+B23/100)) -> 100 | C32: un | F32: 11 | G32: 5.8 | H32: 11.6 | I32: 18.1 | J32: 23.8
A33: Pérdida de carga en las rejas | F33: 12 | G33: 6.7 | H33: 13.4 | I33: 21.2 | J33: 27.4
A34: Rejas limpias | B34: =1.43*(B26^2-(B26*B29)^2)/(2*9.81) -> 0.010712773 | C34: m | F34: 13 | G34: 7.5 | H34: 15.2 | I34: 23.8 | J34: 31
A35: Rejas 50% sucias | B35: =1.43*((2*B26)^2-(B26*B29)^2)/(2*9.81) -> 0.08942837 | C35: m | F35: 14 | G35: 8.5 | H35: 17.3 | I35: 26.6 | J35: 34.8
A36: Altura del agua antes de las rejas a 50% sucias | F36: 15 | G36: 9.4 | H36: 19.1 | I36: 29.2 | J36: 38.4
A37: Altura a caudal máximo | B37: =+$B$35+B19 -> 0.48129537 | C37: m | F37: 16 | G37: 10.8 | H37: 21.1 | I37: 32.4 | J37: 42.5
A38: Altura a caudal medio | B38: =+$B$35+B20 -> 0.30713226 | C38: m
A39: Altura a caudal mínimo | B39: =+$B$35+B21 -> 0.19828031 | C39: m
A40: Mantenimiento de la rejas
A41: Cantidad de material retenido (0,03 - 0,05 - 0,10) | B41: =+B68/1000 -> 0.05 | C41: l/m3/d
A42: Tiempo de limpieza | B42: 2 | C42: d
A43: Longitud del depósito previo a las rejas | B43: 2 | C43: m
...

